<?xml version="1.0" encoding="UTF-8"?>
<testng-results ignored="0" total="7" passed="5" failed="2" skipped="0">
  <reporter-output>
  </reporter-output>
  <suite started-at="2024-10-22T07:43:32 IST" name="Default suite" finished-at="2024-10-22T07:43:33 IST" duration-ms="126">
    <groups>
    </groups>
    <test started-at="2024-10-22T07:43:32 IST" name="Default test" finished-at="2024-10-22T07:43:33 IST" duration-ms="126">
      <class name="TestNGPractice.HardAsertEx1">
        <test-method signature="m1()[pri:0, instance:TestNGPractice.HardAsertEx1@72057ecf]" started-at="2024-10-22T07:43:32 IST" name="m1" finished-at="2024-10-22T07:43:32 IST" duration-ms="19" status="PASS">
          <reporter-output>
          </reporter-output>
        </test-method> <!-- m1 -->
        <test-method signature="m2()[pri:0, instance:TestNGPractice.HardAsertEx1@72057ecf]" started-at="2024-10-22T07:43:32 IST" name="m2" finished-at="2024-10-22T07:43:32 IST" duration-ms="7" status="PASS">
          <reporter-output>
          </reporter-output>
        </test-method> <!-- m2 -->
        <test-method signature="m3()[pri:0, instance:TestNGPractice.HardAsertEx1@72057ecf]" started-at="2024-10-22T07:43:32 IST" name="m3" finished-at="2024-10-22T07:43:32 IST" duration-ms="6" status="FAIL">
          <exception class="java.lang.AssertionError">
            <message>
              <![CDATA[It is Equal =  expected [1] but found [10]]]>
            </message>
            <full-stacktrace>
              <![CDATA[java.lang.AssertionError: It is Equal =  expected [1] but found [10]
at org.testng.Assert.fail(Assert.java:99)
at org.testng.Assert.failNotEquals(Assert.java:1037)
at org.testng.Assert.assertEqualsImpl(Assert.java:140)
at org.testng.Assert.assertEquals(Assert.java:122)
at org.testng.Assert.assertEquals(Assert.java:907)
at TestNGPractice.HardAsertEx1.m3(HardAsertEx1.java:29)
at java.base/jdk.internal.reflect.DirectMethodHandleAccessor.invoke(DirectMethodHandleAccessor.java:103)
at java.base/java.lang.reflect.Method.invoke(Method.java:580)
at org.testng.internal.MethodInvocationHelper.invokeMethod(MethodInvocationHelper.java:133)
at org.testng.internal.TestInvoker.invokeMethod(TestInvoker.java:598)
at org.testng.internal.TestInvoker.invokeTestMethod(TestInvoker.java:173)
at org.testng.internal.MethodRunner.runInSequence(MethodRunner.java:46)
at org.testng.internal.TestInvoker$MethodInvocationAgent.invoke(TestInvoker.java:824)
at org.testng.internal.TestInvoker.invokeTestMethods(TestInvoker.java:146)
at org.testng.internal.TestMethodWorker.invokeTestMethods(TestMethodWorker.java:146)
at org.testng.internal.TestMethodWorker.run(TestMethodWorker.java:128)
at java.base/java.util.ArrayList.forEach(ArrayList.java:1596)
at org.testng.TestRunner.privateRun(TestRunner.java:794)
at org.testng.TestRunner.run(TestRunner.java:596)
at org.testng.SuiteRunner.runTest(SuiteRunner.java:377)
at org.testng.SuiteRunner.runSequentially(SuiteRunner.java:371)
at org.testng.SuiteRunner.privateRun(SuiteRunner.java:332)
at org.testng.SuiteRunner.run(SuiteRunner.java:276)
at org.testng.SuiteRunnerWorker.runSuite(SuiteRunnerWorker.java:53)
at org.testng.SuiteRunnerWorker.run(SuiteRunnerWorker.java:96)
at org.testng.TestNG.runSuitesSequentially(TestNG.java:1212)
at org.testng.TestNG.runSuitesLocally(TestNG.java:1134)
at org.testng.TestNG.runSuites(TestNG.java:1063)
at org.testng.TestNG.run(TestNG.java:1031)
at org.testng.remote.AbstractRemoteTestNG.run(AbstractRemoteTestNG.java:115)
at org.testng.remote.RemoteTestNG.initAndRun(RemoteTestNG.java:293)
at org.testng.remote.RemoteTestNG.main(RemoteTestNG.java:91)
]]>
            </full-stacktrace>
          </exception> <!-- java.lang.AssertionError -->
          <reporter-output>
          </reporter-output>
        </test-method> <!-- m3 -->
        <test-method signature="m4()[pri:0, instance:TestNGPractice.HardAsertEx1@72057ecf]" started-at="2024-10-22T07:43:32 IST" name="m4" finished-at="2024-10-22T07:43:32 IST" duration-ms="5" status="PASS">
          <reporter-output>
          </reporter-output>
        </test-method> <!-- m4 -->
        <test-method signature="m5()[pri:0, instance:TestNGPractice.HardAsertEx1@72057ecf]" started-at="2024-10-22T07:43:32 IST" name="m5" finished-at="2024-10-22T07:43:32 IST" duration-ms="3" status="PASS">
          <reporter-output>
          </reporter-output>
        </test-method> <!-- m5 -->
        <test-method signature="m6()[pri:0, instance:TestNGPractice.HardAsertEx1@72057ecf]" started-at="2024-10-22T07:43:32 IST" name="m6" finished-at="2024-10-22T07:43:32 IST" duration-ms="1" status="FAIL">
          <exception class="java.lang.AssertionError">
            <message>
              <![CDATA[it is not null expected [null] but found [hi]]]>
            </message>
            <full-stacktrace>
              <![CDATA[java.lang.AssertionError: it is not null expected [null] but found [hi]
at org.testng.Assert.fail(Assert.java:99)
at org.testng.Assert.failNotSame(Assert.java:1033)
at org.testng.Assert.assertNull(Assert.java:965)
at TestNGPractice.HardAsertEx1.m6(HardAsertEx1.java:50)
at java.base/jdk.internal.reflect.DirectMethodHandleAccessor.invoke(DirectMethodHandleAccessor.java:103)
at java.base/java.lang.reflect.Method.invoke(Method.java:580)
at org.testng.internal.MethodInvocationHelper.invokeMethod(MethodInvocationHelper.java:133)
at org.testng.internal.TestInvoker.invokeMethod(TestInvoker.java:598)
at org.testng.internal.TestInvoker.invokeTestMethod(TestInvoker.java:173)
at org.testng.internal.MethodRunner.runInSequence(MethodRunner.java:46)
at org.testng.internal.TestInvoker$MethodInvocationAgent.invoke(TestInvoker.java:824)
at org.testng.internal.TestInvoker.invokeTestMethods(TestInvoker.java:146)
at org.testng.internal.TestMethodWorker.invokeTestMethods(TestMethodWorker.java:146)
at org.testng.internal.TestMethodWorker.run(TestMethodWorker.java:128)
at java.base/java.util.ArrayList.forEach(ArrayList.java:1596)
at org.testng.TestRunner.privateRun(TestRunner.java:794)
at org.testng.TestRunner.run(TestRunner.java:596)
at org.testng.SuiteRunner.runTest(SuiteRunner.java:377)
at org.testng.SuiteRunner.runSequentially(SuiteRunner.java:371)
at org.testng.SuiteRunner.privateRun(SuiteRunner.java:332)
at org.testng.SuiteRunner.run(SuiteRunner.java:276)
at org.testng.SuiteRunnerWorker.runSuite(SuiteRunnerWorker.java:53)
at org.testng.SuiteRunnerWorker.run(SuiteRunnerWorker.java:96)
at org.testng.TestNG.runSuitesSequentially(TestNG.java:1212)
at org.testng.TestNG.runSuitesLocally(TestNG.java:1134)
at org.testng.TestNG.runSuites(TestNG.java:1063)
at org.testng.TestNG.run(TestNG.java:1031)
at org.testng.remote.AbstractRemoteTestNG.run(AbstractRemoteTestNG.java:115)
at org.testng.remote.RemoteTestNG.initAndRun(RemoteTestNG.java:293)
at org.testng.remote.RemoteTestNG.main(RemoteTestNG.java:91)
]]>
            </full-stacktrace>
          </exception> <!-- java.lang.AssertionError -->
          <reporter-output>
          </reporter-output>
        </test-method> <!-- m6 -->
        <test-method signature="m7()[pri:0, instance:TestNGPractice.HardAsertEx1@72057ecf]" started-at="2024-10-22T07:43:32 IST" name="m7" finished-at="2024-10-22T07:43:32 IST" duration-ms="4" status="PASS">
          <reporter-output>
          </reporter-output>
        </test-method> <!-- m7 -->
      </class> <!-- TestNGPractice.HardAsertEx1 -->
    </test> <!-- Default test -->
  </suite> <!-- Default suite -->
</testng-results>
